{"uuid": "ee972b6d-c6a4-4c59-96c1-5b6b7eedda5d", "children": ["c770ce18-6683-418c-809b-7aebb8da56b2", "88e8d259-34f1-4b83-919c-7438d4e13a81"], "befores": [{"name": "_xunit_setup_class_fixture_TestAddMember", "status": "broken", "statusDetails": {"message": "TypeError: __init__() got an unexpected keyword argument 'capabilities'\n", "trace": "  File \"D:\\pycharm\\Selenium\\venv\\lib\\site-packages\\pluggy\\_callers.py\", line 39, in _multicall\n    res = hook_impl.function(*args)\n  File \"D:\\pycharm\\Selenium\\venv\\lib\\site-packages\\_pytest\\fixtures.py\", line 1130, in pytest_fixture_setup\n    result = call_fixture_func(fixturefunc, request, kwargs)\n  File \"D:\\pycharm\\Selenium\\venv\\lib\\site-packages\\_pytest\\fixtures.py\", line 902, in call_fixture_func\n    fixture_result = next(generator)\n  File \"D:\\pycharm\\Selenium\\venv\\lib\\site-packages\\_pytest\\python.py\", line 864, in xunit_setup_class_fixture\n    _call_with_optional_argument(func, self.obj)\n  File \"D:\\pycharm\\Selenium\\venv\\lib\\site-packages\\_pytest\\python.py\", line 785, in _call_with_optional_argument\n    func(arg)\n  File \"D:\\pycharm\\Selenium\\testcase\\test_add_member.py\", line 12, in setup_class\n    self.home = LoginPage().login()\n  File \"D:\\pycharm\\Selenium\\page\\base.py\", line 21, in __init__\n    self.driver = webdriver.Remote(command_executor='http://192.168.254.128:5444/wd/hub', capabilities=capabilities)\n"}, "start": 1690513521292, "stop": 1690513521292}], "start": 1690513521292, "stop": 1690513521490}