{"uuid": "ffedc21b-1c87-4b18-8814-d02113ac88c5", "children": ["67fe1598-2f0f-41e6-9226-89ce092b5cda", "802ee8f9-8d0e-4113-b152-c4e16604cd8e"], "befores": [{"name": "_xunit_setup_class_fixture_TestAddMember", "status": "broken", "statusDetails": {"message": "urllib3.exceptions.MaxRetryError: HTTPConnectionPool(host='172.17.0.4', port=5555): Max retries exceeded with url: /wd/hub/session (Caused by NewConnectionError('<urllib3.connection.HTTPConnection object at 0x0000021D71282F40>: Failed to establish a new connection: [WinError 10060] 由于连接方在一段时间后没有正确答复或连接的主机没有反应，连接尝试失败。'))\n", "trace": "  File \"D:\\pycharm\\Selenium\\venv\\lib\\site-packages\\pluggy\\_callers.py\", line 39, in _multicall\n    res = hook_impl.function(*args)\n  File \"D:\\pycharm\\Selenium\\venv\\lib\\site-packages\\_pytest\\fixtures.py\", line 1130, in pytest_fixture_setup\n    result = call_fixture_func(fixturefunc, request, kwargs)\n  File \"D:\\pycharm\\Selenium\\venv\\lib\\site-packages\\_pytest\\fixtures.py\", line 902, in call_fixture_func\n    fixture_result = next(generator)\n  File \"D:\\pycharm\\Selenium\\venv\\lib\\site-packages\\_pytest\\python.py\", line 864, in xunit_setup_class_fixture\n    _call_with_optional_argument(func, self.obj)\n  File \"D:\\pycharm\\Selenium\\venv\\lib\\site-packages\\_pytest\\python.py\", line 785, in _call_with_optional_argument\n    func(arg)\n  File \"D:\\pycharm\\Selenium\\testcase\\test_add_member.py\", line 12, in setup_class\n    self.home = LoginPage().login()\n  File \"D:\\pycharm\\Selenium\\page\\base.py\", line 20, in __init__\n    capabilities = {}\n  File \"D:\\pycharm\\Selenium\\venv\\lib\\site-packages\\selenium\\webdriver\\remote\\webdriver.py\", line 275, in __init__\n    self.start_session(capabilities, browser_profile)\n  File \"D:\\pycharm\\Selenium\\venv\\lib\\site-packages\\selenium\\webdriver\\remote\\webdriver.py\", line 365, in start_session\n    response = self.execute(Command.NEW_SESSION, parameters)\n  File \"D:\\pycharm\\Selenium\\venv\\lib\\site-packages\\selenium\\webdriver\\remote\\webdriver.py\", line 428, in execute\n    response = self.command_executor.execute(driver_command, params)\n  File \"D:\\pycharm\\Selenium\\venv\\lib\\site-packages\\selenium\\webdriver\\remote\\remote_connection.py\", line 347, in execute\n    return self._request(command_info[0], url, body=data)\n  File \"D:\\pycharm\\Selenium\\venv\\lib\\site-packages\\selenium\\webdriver\\remote\\remote_connection.py\", line 369, in _request\n    response = self._conn.request(method, url, body=body, headers=headers)\n  File \"D:\\pycharm\\Selenium\\venv\\lib\\site-packages\\urllib3\\request.py\", line 78, in request\n    return self.request_encode_body(\n  File \"D:\\pycharm\\Selenium\\venv\\lib\\site-packages\\urllib3\\request.py\", line 170, in request_encode_body\n    return self.urlopen(method, url, **extra_kw)\n  File \"D:\\pycharm\\Selenium\\venv\\lib\\site-packages\\urllib3\\poolmanager.py\", line 376, in urlopen\n    response = conn.urlopen(method, u.request_uri, **kw)\n  File \"D:\\pycharm\\Selenium\\venv\\lib\\site-packages\\urllib3\\connectionpool.py\", line 826, in urlopen\n    return self.urlopen(\n  File \"D:\\pycharm\\Selenium\\venv\\lib\\site-packages\\urllib3\\connectionpool.py\", line 826, in urlopen\n    return self.urlopen(\n  File \"D:\\pycharm\\Selenium\\venv\\lib\\site-packages\\urllib3\\connectionpool.py\", line 826, in urlopen\n    return self.urlopen(\n  File \"D:\\pycharm\\Selenium\\venv\\lib\\site-packages\\urllib3\\connectionpool.py\", line 798, in urlopen\n    retries = retries.increment(\n  File \"D:\\pycharm\\Selenium\\venv\\lib\\site-packages\\urllib3\\util\\retry.py\", line 592, in increment\n    raise MaxRetryError(_pool, url, error or ResponseError(cause))\n"}, "start": 1690512807473, "stop": 1690512891597}], "start": 1690512807473, "stop": 1690512892115}